<robot name="cooper" version="1.6">
  
  <link name="robotiq_hande_gripper_body">
    <inertial>
      <mass value="1" />
      <inertia ixx="0.1" ixy="0" ixz="0" iyy="0.1" iyz="0" izz="0.1" />
      <origin rpy="0 0 0" xyz="0 0 0" />
    </inertial>
    <visual name="visual1">
      <origin rpy="0 0 0" xyz="0 0 0" />
      <geometry>
        <mesh filename="robotiq_hande/robotiq_hande_body_c01.stl">
        </mesh>
      </geometry>
    </visual>
    <visual name="visual2">
      <origin rpy="0 0 0" xyz="0 0 0" />
      <geometry>
        <mesh filename="robotiq_hande/robotiq_hande_body_c02.stl">
        </mesh>
      </geometry>
    </visual>
    <collision name="collision1">
      <origin rpy="0 0 0" xyz="0 0 0" />
      <geometry>
        <mesh filename="robotiq_hande/robotiq_hande_body_c01.stl">
        </mesh>
      </geometry>
    </collision>
    <collision name="collision2">
      <origin rpy="0 0 0" xyz="0 0 0" />
      <geometry>
        <mesh filename="robotiq_hande/robotiq_hande_body_c02.stl">
        </mesh>
      </geometry>
    </collision>
  </link>


  <link name="robotiq_hande_sticky_link">
    <inertial>
      <mass value="0.001" />
      <origin rpy="0 0 0" xyz="0 0 0" />
      <inertia ixx="0.00000160833269" ixy="0" ixz="0" iyy="0.00000160833269" iyz="0" izz="0.0000032" />
    </inertial>
    <collision name="collision_grip">
      <origin rpy="0 0 0" xyz="0 0 0.0" />
      <geometry>
        <cylinder length="0.04" radius="0.02">
        </cylinder>
      </geometry>
    </collision>
  </link>


  <link name="robotiq_hande_gripper_finger1">
    <inertial>
      <mass value="1" />
      <inertia ixx="0.1" ixy="0" ixz="0" iyy="0.1" iyz="0" izz="0.1" />
    </inertial>
    <visual name="visual1">
      <origin rpy="0 0 0" xyz="0 0 0" />
      <geometry>
        <mesh filename="robotiq_hande/robotiq_hande_finger_c01.stl">
        </mesh>
      </geometry>
    </visual>
    <visual name="visual2">
      <origin rpy="0 0 0" xyz="0 0 0" />
      <geometry>
        <mesh filename="robotiq_hande/robotiq_hande_finger_c02.stl">
        </mesh>
      </geometry>
    </visual>
    <visual name="visual3">
      <origin rpy="0 0 0" xyz="0 0 0" />
      <geometry>
        <mesh filename="robotiq_hande/robotiq_hande_finger_c03.stl">
        </mesh>
      </geometry>
    </visual>
    <visual name="visual4">
      <origin rpy="0 0 0" xyz="0 0 0" />
      <geometry>
        <mesh filename="robotiq_hande/robotiq_hande_finger_c04.stl">
        </mesh>
      </geometry>
    </visual>
    <collision name="collision1">
      <origin rpy="0 0 0" xyz="0 0 0" />
      <geometry>
        <mesh filename="robotiq_hande/robotiq_hande_finger_c01.stl">
        </mesh>
      </geometry>
    </collision>
    <collision name="collision2">
      <origin rpy="0 0 0" xyz="0 0 0" />
      <geometry>
        <mesh filename="robotiq_hande/robotiq_hande_finger_c02.stl">
        </mesh>
      </geometry>
    </collision>
    <collision name="collision3">
      <origin rpy="0 0 0" xyz="0 0 0" />
      <geometry>
        <mesh filename="robotiq_hande/robotiq_hande_finger_c03.stl">
        </mesh>
      </geometry>
    </collision>
    <collision name="collision4">
      <origin rpy="0 0 0" xyz="0 0 0" />
      <geometry>
        <mesh filename="robotiq_hande/robotiq_hande_finger_c04.stl">
        </mesh>
      </geometry>
    </collision>
  </link>
  
  
  <link name="robotiq_hande_gripper_finger2">
    <inertial>
      <mass value="1" />
      <inertia ixx="0.1" ixy="0" ixz="0" iyy="0.1" iyz="0" izz="0.1" />
    </inertial>
    <visual name="visual1">
      <origin rpy="0 0 3.14157" xyz="0 0 0" />
      <geometry>
        <mesh filename="robotiq_hande/robotiq_hande_finger_c01.stl">
        </mesh>
      </geometry>
    </visual>
    <visual name="visual2">
      <origin rpy="0 0 3.14157" xyz="0 0 0" />
      <geometry>
        <mesh filename="robotiq_hande/robotiq_hande_finger_c02.stl">
        </mesh>
      </geometry>
    </visual>
    <visual name="visual3">
      <origin rpy="0 0 3.14157" xyz="0 0 0" />
      <geometry>
        <mesh filename="robotiq_hande/robotiq_hande_finger_c03.stl">
        </mesh>
      </geometry>
    </visual>
    <visual name="visual4">
      <origin rpy="0 0 3.14157" xyz="0 0 0" />
      <geometry>
        <mesh filename="robotiq_hande/robotiq_hande_finger_c04.stl">
        </mesh>
      </geometry>
    </visual>
    <collision name="collision1">
      <origin rpy="0 0 3.14157" xyz="0 0 0" />
      <geometry>
        <mesh filename="robotiq_hande/robotiq_hande_finger_c01.stl">
        </mesh>
      </geometry>
    </collision>
    <collision name="collision2">
      <origin rpy="0 0 3.14157" xyz="0 0 0" />
      <geometry>
        <mesh filename="robotiq_hande/robotiq_hande_finger_c02.stl">
        </mesh>
      </geometry>
    </collision>
    <collision name="collision3">
      <origin rpy="0 0 3.14157" xyz="0 0 0" />
      <geometry>
        <mesh filename="robotiq_hande/robotiq_hande_finger_c03.stl">
        </mesh>
      </geometry>
    </collision>
    <collision name="collision4">
      <origin rpy="0 0 3.14157" xyz="0 0 0" />
      <geometry>
        <mesh filename="robotiq_hande/robotiq_hande_finger_c04.stl">
        </mesh>
      </geometry>
    </collision>
  </link>


  <link name="tcp_link">
    <inertial>
      <mass value="0.001" />
      <origin rpy="0 0 0" xyz="0 0 0" />
      <inertia ixx="0.00000160833269" ixy="0" ixz="0" iyy="0.00000160833269" iyz="0" izz="0.0000032" />
    </inertial>
    <visual> 
      <geometry>
        <sphere radius="0.002"></sphere>
      </geometry>
    </visual>
  </link>
  
  
  <joint name="sticky_link_joint" type="fixed">
    <parent link="robotiq_hande_gripper_body" />
    <child link="robotiq_hande_sticky_link" />
    <origin rpy="0.0 -0.0 0.0" xyz="0.0 0.0 0.128" />
  </joint>


  <joint name="finger1" type="prismatic">
    <parent link="robotiq_hande_gripper_body" />
    <child link="robotiq_hande_gripper_finger1" />
    <limit lower="0" upper="0.025" />
    <axis xyz="0 1 0" />
    <origin rpy="0.0 -0.0 0.0" xyz="0.0 0.0 0.0" />
  </joint>
  
  
  <joint name="finger2" type="prismatic">
    <parent link="robotiq_hande_gripper_body" />
    <child link="robotiq_hande_gripper_finger2" />
    <limit lower="0" upper="0.025" />
    <axis xyz="0 -1 0" />
    <origin rpy="0.0 -0.0 0.0" xyz="0.0 0.0 0.0" />
  </joint>
  

  <joint name="tcp" type="fixed">
    <parent link="robotiq_hande_gripper_body" />
    <child link="tcp_link" />
    <origin rpy="0.0 -1.5707963267948966 0" xyz="0 0 0.229846" />
  </joint>

</robot>